[2025-07-03T14:49:19.085+0000] {local_task_job_runner.py:120} INFO - ::group::Pre task execution logs
[2025-07-03T14:49:19.105+0000] {taskinstance.py:2073} INFO - Dependencies all met for dep_context=non-requeueable deps ti=<TaskInstance: connect_to_minio.explore_bucket_structure manual__2025-07-03T12:48:33.639150+00:00 [queued]>
[2025-07-03T14:49:19.113+0000] {taskinstance.py:2073} INFO - Dependencies all met for dep_context=requeueable deps ti=<TaskInstance: connect_to_minio.explore_bucket_structure manual__2025-07-03T12:48:33.639150+00:00 [queued]>
[2025-07-03T14:49:19.114+0000] {taskinstance.py:2303} INFO - Starting attempt 9 of 9
[2025-07-03T14:49:19.120+0000] {taskinstance.py:2327} INFO - Executing <Task(PythonOperator): explore_bucket_structure> on 2025-07-03 12:48:33.639150+00:00
[2025-07-03T14:49:19.125+0000] {standard_task_runner.py:63} INFO - Started process 271 to run task
[2025-07-03T14:49:19.127+0000] {standard_task_runner.py:90} INFO - Running: ['***', 'tasks', 'run', 'connect_to_minio', 'explore_bucket_structure', 'manual__2025-07-03T12:48:33.639150+00:00', '--job-id', '41', '--raw', '--subdir', 'DAGS_FOLDER/test_connection_to_minio.py', '--cfg-path', '/tmp/tmpx4kixs9a']
[2025-07-03T14:49:19.129+0000] {standard_task_runner.py:91} INFO - Job 41: Subtask explore_bucket_structure
[2025-07-03T14:49:19.138+0000] {logging_mixin.py:188} WARNING - /home/***/.local/lib/python3.11/site-packages/***/settings.py:195 DeprecationWarning: The sql_alchemy_conn option in [core] has been moved to the sql_alchemy_conn option in [database] - the old setting has been used, but please update your config.
[2025-07-03T14:49:19.161+0000] {task_command.py:426} INFO - Running <TaskInstance: connect_to_minio.explore_bucket_structure manual__2025-07-03T12:48:33.639150+00:00 [running]> on host 1b628c5cb8e4
[2025-07-03T14:49:19.211+0000] {taskinstance.py:2644} INFO - Exporting env vars: AIRFLOW_CTX_DAG_OWNER='***' AIRFLOW_CTX_DAG_ID='connect_to_minio' AIRFLOW_CTX_TASK_ID='explore_bucket_structure' AIRFLOW_CTX_EXECUTION_DATE='2025-07-03T12:48:33.639150+00:00' AIRFLOW_CTX_TRY_NUMBER='9' AIRFLOW_CTX_DAG_RUN_ID='manual__2025-07-03T12:48:33.639150+00:00'
[2025-07-03T14:49:19.211+0000] {taskinstance.py:430} INFO - ::endgroup::
[2025-07-03T14:49:19.217+0000] {logging_mixin.py:188} INFO - Error exploring bucket: [Errno 2] No such file or directory: '/opt/***/credentials/credentials-minio'
[2025-07-03T14:49:19.218+0000] {taskinstance.py:441} INFO - ::group::Post task execution logs
[2025-07-03T14:49:19.218+0000] {taskinstance.py:2890} ERROR - Task failed with exception
Traceback (most recent call last):
  File "/home/airflow/.local/lib/python3.11/site-packages/airflow/models/taskinstance.py", line 465, in _execute_task
    result = _execute_callable(context=context, **execute_callable_kwargs)
             ^^^^^^^^^^^^^^^^^^^^^^^^^^^^^^^^^^^^^^^^^^^^^^^^^^^^^^^^^^^^^
  File "/home/airflow/.local/lib/python3.11/site-packages/airflow/models/taskinstance.py", line 432, in _execute_callable
    return execute_callable(context=context, **execute_callable_kwargs)
           ^^^^^^^^^^^^^^^^^^^^^^^^^^^^^^^^^^^^^^^^^^^^^^^^^^^^^^^^^^^^
  File "/home/airflow/.local/lib/python3.11/site-packages/airflow/models/baseoperator.py", line 400, in wrapper
    return func(self, *args, **kwargs)
           ^^^^^^^^^^^^^^^^^^^^^^^^^^^
  File "/home/airflow/.local/lib/python3.11/site-packages/airflow/operators/python.py", line 235, in execute
    return_value = self.execute_callable()
                   ^^^^^^^^^^^^^^^^^^^^^^^
  File "/home/airflow/.local/lib/python3.11/site-packages/airflow/operators/python.py", line 252, in execute_callable
    return self.python_callable(*self.op_args, **self.op_kwargs)
           ^^^^^^^^^^^^^^^^^^^^^^^^^^^^^^^^^^^^^^^^^^^^^^^^^^^^^
  File "/opt/airflow/dags/test_connection_to_minio.py", line 34, in explore_bucket_structure
    s3_client = create_minio_client()
                ^^^^^^^^^^^^^^^^^^^^^
  File "/opt/airflow/dags/test_connection_to_minio.py", line 12, in create_minio_client
    with open('/opt/airflow/credentials/credentials-minio') as credentials_file:
         ^^^^^^^^^^^^^^^^^^^^^^^^^^^^^^^^^^^^^^^^^^^^^^^^^^
FileNotFoundError: [Errno 2] No such file or directory: '/opt/airflow/credentials/credentials-minio'
[2025-07-03T14:49:19.227+0000] {taskinstance.py:1205} INFO - Marking task as FAILED. dag_id=connect_to_minio, task_id=explore_bucket_structure, execution_date=20250703T124833, start_date=20250703T144919, end_date=20250703T144919
[2025-07-03T14:49:19.233+0000] {standard_task_runner.py:110} ERROR - Failed to execute job 41 for task explore_bucket_structure ([Errno 2] No such file or directory: '/opt/airflow/credentials/credentials-minio'; 271)
[2025-07-03T14:49:19.259+0000] {local_task_job_runner.py:240} INFO - Task exited with return code 1
[2025-07-03T14:49:19.273+0000] {taskinstance.py:3482} INFO - 0 downstream tasks scheduled from follow-on schedule check
[2025-07-03T14:49:19.275+0000] {local_task_job_runner.py:222} INFO - ::endgroup::
