[2025-07-07T06:53:39.203+0000] {local_task_job_runner.py:120} INFO - ::group::Pre task execution logs
[2025-07-07T06:53:39.217+0000] {taskinstance.py:2073} INFO - Dependencies all met for dep_context=non-requeueable deps ti=<TaskInstance: minio_ga4_new_file_detector.detect_new_ga4_data manual__2025-07-07T06:53:38.076557+00:00 [queued]>
[2025-07-07T06:53:39.221+0000] {taskinstance.py:2073} INFO - Dependencies all met for dep_context=requeueable deps ti=<TaskInstance: minio_ga4_new_file_detector.detect_new_ga4_data manual__2025-07-07T06:53:38.076557+00:00 [queued]>
[2025-07-07T06:53:39.221+0000] {taskinstance.py:2303} INFO - Starting attempt 1 of 2
[2025-07-07T06:53:39.226+0000] {taskinstance.py:2327} INFO - Executing <Task(PythonOperator): detect_new_ga4_data> on 2025-07-07 06:53:38.076557+00:00
[2025-07-07T06:53:39.230+0000] {standard_task_runner.py:63} INFO - Started process 2550 to run task
[2025-07-07T06:53:39.232+0000] {standard_task_runner.py:90} INFO - Running: ['***', 'tasks', 'run', 'minio_ga4_new_file_detector', 'detect_new_ga4_data', 'manual__2025-07-07T06:53:38.076557+00:00', '--job-id', '140', '--raw', '--subdir', 'DAGS_FOLDER/dag_automatic.py', '--cfg-path', '/tmp/tmpsh3ek9ov']
[2025-07-07T06:53:39.234+0000] {standard_task_runner.py:91} INFO - Job 140: Subtask detect_new_ga4_data
[2025-07-07T06:53:39.243+0000] {logging_mixin.py:188} WARNING - /home/***/.local/lib/python3.11/site-packages/***/settings.py:195 DeprecationWarning: The sql_alchemy_conn option in [core] has been moved to the sql_alchemy_conn option in [database] - the old setting has been used, but please update your config.
[2025-07-07T06:53:39.261+0000] {task_command.py:426} INFO - Running <TaskInstance: minio_ga4_new_file_detector.detect_new_ga4_data manual__2025-07-07T06:53:38.076557+00:00 [running]> on host 34b334fe6b50
[2025-07-07T06:53:39.307+0000] {taskinstance.py:2644} INFO - Exporting env vars: AIRFLOW_CTX_DAG_OWNER='***' AIRFLOW_CTX_DAG_ID='minio_ga4_new_file_detector' AIRFLOW_CTX_TASK_ID='detect_new_ga4_data' AIRFLOW_CTX_EXECUTION_DATE='2025-07-07T06:53:38.076557+00:00' AIRFLOW_CTX_TRY_NUMBER='1' AIRFLOW_CTX_DAG_RUN_ID='manual__2025-07-07T06:53:38.076557+00:00'
[2025-07-07T06:53:39.307+0000] {taskinstance.py:430} INFO - ::endgroup::
[2025-07-07T06:53:39.377+0000] {taskinstance.py:441} INFO - ::group::Post task execution logs
[2025-07-07T06:53:39.377+0000] {taskinstance.py:2890} ERROR - Task failed with exception
Traceback (most recent call last):
  File "/home/airflow/.local/lib/python3.11/site-packages/airflow/models/taskinstance.py", line 465, in _execute_task
    result = _execute_callable(context=context, **execute_callable_kwargs)
             ^^^^^^^^^^^^^^^^^^^^^^^^^^^^^^^^^^^^^^^^^^^^^^^^^^^^^^^^^^^^^
  File "/home/airflow/.local/lib/python3.11/site-packages/airflow/models/taskinstance.py", line 432, in _execute_callable
    return execute_callable(context=context, **execute_callable_kwargs)
           ^^^^^^^^^^^^^^^^^^^^^^^^^^^^^^^^^^^^^^^^^^^^^^^^^^^^^^^^^^^^
  File "/home/airflow/.local/lib/python3.11/site-packages/airflow/models/baseoperator.py", line 400, in wrapper
    return func(self, *args, **kwargs)
           ^^^^^^^^^^^^^^^^^^^^^^^^^^^
  File "/home/airflow/.local/lib/python3.11/site-packages/airflow/operators/python.py", line 235, in execute
    return_value = self.execute_callable()
                   ^^^^^^^^^^^^^^^^^^^^^^^
  File "/home/airflow/.local/lib/python3.11/site-packages/airflow/operators/python.py", line 252, in execute_callable
    return self.python_callable(*self.op_args, **self.op_kwargs)
           ^^^^^^^^^^^^^^^^^^^^^^^^^^^^^^^^^^^^^^^^^^^^^^^^^^^^^
  File "/opt/airflow/dags/dag_automatic.py", line 33, in detect_new_ga4_data
    last_processed_timestamp_str = Variable.get(
                                   ^^^^^^^^^^^^^
TypeError: Variable.get() got an unexpected keyword argument 'default'
[2025-07-07T06:53:39.385+0000] {taskinstance.py:1205} INFO - Marking task as UP_FOR_RETRY. dag_id=minio_ga4_new_file_detector, task_id=detect_new_ga4_data, execution_date=20250707T065338, start_date=20250707T065339, end_date=20250707T065339
[2025-07-07T06:53:39.393+0000] {standard_task_runner.py:110} ERROR - Failed to execute job 140 for task detect_new_ga4_data (Variable.get() got an unexpected keyword argument 'default'; 2550)
[2025-07-07T06:53:39.404+0000] {local_task_job_runner.py:240} INFO - Task exited with return code 1
[2025-07-07T06:53:39.417+0000] {taskinstance.py:3482} INFO - 0 downstream tasks scheduled from follow-on schedule check
[2025-07-07T06:53:39.418+0000] {local_task_job_runner.py:222} INFO - ::endgroup::
