[2025-07-03T12:43:41.500+0000] {local_task_job_runner.py:120} INFO - ::group::Pre task execution logs
[2025-07-03T12:43:41.518+0000] {taskinstance.py:2073} INFO - Dependencies all met for dep_context=non-requeueable deps ti=<TaskInstance: connect_to_minio.connect_to_minio manual__2025-07-03T12:37:11.284573+00:00 [queued]>
[2025-07-03T12:43:41.521+0000] {taskinstance.py:2073} INFO - Dependencies all met for dep_context=requeueable deps ti=<TaskInstance: connect_to_minio.connect_to_minio manual__2025-07-03T12:37:11.284573+00:00 [queued]>
[2025-07-03T12:43:41.521+0000] {taskinstance.py:2303} INFO - Starting attempt 4 of 5
[2025-07-03T12:43:41.526+0000] {taskinstance.py:2327} INFO - Executing <Task(PythonOperator): connect_to_minio> on 2025-07-03 12:37:11.284573+00:00
[2025-07-03T12:43:41.530+0000] {standard_task_runner.py:63} INFO - Started process 374 to run task
[2025-07-03T12:43:41.532+0000] {standard_task_runner.py:90} INFO - Running: ['***', 'tasks', 'run', 'connect_to_minio', 'connect_to_minio', 'manual__2025-07-03T12:37:11.284573+00:00', '--job-id', '6', '--raw', '--subdir', 'DAGS_FOLDER/test_connection_to_minio.py', '--cfg-path', '/tmp/tmp9mysbo7w']
[2025-07-03T12:43:41.533+0000] {standard_task_runner.py:91} INFO - Job 6: Subtask connect_to_minio
[2025-07-03T12:43:41.545+0000] {logging_mixin.py:188} WARNING - /home/***/.local/lib/python3.11/site-packages/***/settings.py:195 DeprecationWarning: The sql_alchemy_conn option in [core] has been moved to the sql_alchemy_conn option in [database] - the old setting has been used, but please update your config.
[2025-07-03T12:43:41.565+0000] {task_command.py:426} INFO - Running <TaskInstance: connect_to_minio.connect_to_minio manual__2025-07-03T12:37:11.284573+00:00 [running]> on host 442ae42bcd6d
[2025-07-03T12:43:41.615+0000] {taskinstance.py:2644} INFO - Exporting env vars: AIRFLOW_CTX_DAG_OWNER='hosi04' AIRFLOW_CTX_DAG_ID='connect_to_minio' AIRFLOW_CTX_TASK_ID='connect_to_minio' AIRFLOW_CTX_EXECUTION_DATE='2025-07-03T12:37:11.284573+00:00' AIRFLOW_CTX_TRY_NUMBER='4' AIRFLOW_CTX_DAG_RUN_ID='manual__2025-07-03T12:37:11.284573+00:00'
[2025-07-03T12:43:41.615+0000] {taskinstance.py:430} INFO - ::endgroup::
[2025-07-03T12:43:41.622+0000] {taskinstance.py:441} INFO - ::group::Post task execution logs
[2025-07-03T12:43:41.622+0000] {taskinstance.py:2890} ERROR - Task failed with exception
Traceback (most recent call last):
  File "/home/airflow/.local/lib/python3.11/site-packages/airflow/models/taskinstance.py", line 465, in _execute_task
    result = _execute_callable(context=context, **execute_callable_kwargs)
             ^^^^^^^^^^^^^^^^^^^^^^^^^^^^^^^^^^^^^^^^^^^^^^^^^^^^^^^^^^^^^
  File "/home/airflow/.local/lib/python3.11/site-packages/airflow/models/taskinstance.py", line 432, in _execute_callable
    return execute_callable(context=context, **execute_callable_kwargs)
           ^^^^^^^^^^^^^^^^^^^^^^^^^^^^^^^^^^^^^^^^^^^^^^^^^^^^^^^^^^^^
  File "/home/airflow/.local/lib/python3.11/site-packages/airflow/models/baseoperator.py", line 400, in wrapper
    return func(self, *args, **kwargs)
           ^^^^^^^^^^^^^^^^^^^^^^^^^^^
  File "/home/airflow/.local/lib/python3.11/site-packages/airflow/operators/python.py", line 235, in execute
    return_value = self.execute_callable()
                   ^^^^^^^^^^^^^^^^^^^^^^^
  File "/home/airflow/.local/lib/python3.11/site-packages/airflow/operators/python.py", line 252, in execute_callable
    return self.python_callable(*self.op_args, **self.op_kwargs)
           ^^^^^^^^^^^^^^^^^^^^^^^^^^^^^^^^^^^^^^^^^^^^^^^^^^^^^
  File "/opt/airflow/dags/test_connection_to_minio.py", line 11, in connect_to_minio
    with open("/opt/airflow/credentials/credentials-minio.json") as f:
         ^^^^^^^^^^^^^^^^^^^^^^^^^^^^^^^^^^^^^^^^^^^^^^^^^^^^^^^
FileNotFoundError: [Errno 2] No such file or directory: '/opt/airflow/credentials/credentials-minio.json'
[2025-07-03T12:43:41.629+0000] {taskinstance.py:1205} INFO - Marking task as UP_FOR_RETRY. dag_id=connect_to_minio, task_id=connect_to_minio, execution_date=20250703T123711, start_date=20250703T124341, end_date=20250703T124341
[2025-07-03T12:43:41.639+0000] {standard_task_runner.py:110} ERROR - Failed to execute job 6 for task connect_to_minio ([Errno 2] No such file or directory: '/opt/airflow/credentials/credentials-minio.json'; 374)
[2025-07-03T12:43:41.663+0000] {local_task_job_runner.py:240} INFO - Task exited with return code 1
[2025-07-03T12:43:41.677+0000] {taskinstance.py:3482} INFO - 0 downstream tasks scheduled from follow-on schedule check
[2025-07-03T12:43:41.677+0000] {local_task_job_runner.py:222} INFO - ::endgroup::
