[2025-07-03T12:48:34.520+0000] {local_task_job_runner.py:120} INFO - ::group::Pre task execution logs
[2025-07-03T12:48:34.538+0000] {taskinstance.py:2073} INFO - Dependencies all met for dep_context=non-requeueable deps ti=<TaskInstance: connect_to_minio.connect_to_minio manual__2025-07-03T12:48:33.639150+00:00 [queued]>
[2025-07-03T12:48:34.542+0000] {taskinstance.py:2073} INFO - Dependencies all met for dep_context=requeueable deps ti=<TaskInstance: connect_to_minio.connect_to_minio manual__2025-07-03T12:48:33.639150+00:00 [queued]>
[2025-07-03T12:48:34.542+0000] {taskinstance.py:2303} INFO - Starting attempt 1 of 2
[2025-07-03T12:48:34.548+0000] {taskinstance.py:2327} INFO - Executing <Task(PythonOperator): connect_to_minio> on 2025-07-03 12:48:33.639150+00:00
[2025-07-03T12:48:34.552+0000] {standard_task_runner.py:63} INFO - Started process 220 to run task
[2025-07-03T12:48:34.554+0000] {standard_task_runner.py:90} INFO - Running: ['***', 'tasks', 'run', 'connect_to_minio', 'connect_to_minio', 'manual__2025-07-03T12:48:33.639150+00:00', '--job-id', '2', '--raw', '--subdir', 'DAGS_FOLDER/test_connection_to_minio.py', '--cfg-path', '/tmp/tmp_aumk0kw']
[2025-07-03T12:48:34.555+0000] {standard_task_runner.py:91} INFO - Job 2: Subtask connect_to_minio
[2025-07-03T12:48:34.563+0000] {logging_mixin.py:188} WARNING - /home/***/.local/lib/python3.11/site-packages/***/settings.py:195 DeprecationWarning: The sql_alchemy_conn option in [core] has been moved to the sql_alchemy_conn option in [database] - the old setting has been used, but please update your config.
[2025-07-03T12:48:34.585+0000] {task_command.py:426} INFO - Running <TaskInstance: connect_to_minio.connect_to_minio manual__2025-07-03T12:48:33.639150+00:00 [running]> on host 8cef375d7ad3
[2025-07-03T12:48:34.633+0000] {taskinstance.py:2644} INFO - Exporting env vars: AIRFLOW_CTX_DAG_OWNER='hosi04' AIRFLOW_CTX_DAG_ID='connect_to_minio' AIRFLOW_CTX_TASK_ID='connect_to_minio' AIRFLOW_CTX_EXECUTION_DATE='2025-07-03T12:48:33.639150+00:00' AIRFLOW_CTX_TRY_NUMBER='1' AIRFLOW_CTX_DAG_RUN_ID='manual__2025-07-03T12:48:33.639150+00:00'
[2025-07-03T12:48:34.633+0000] {taskinstance.py:430} INFO - ::endgroup::
[2025-07-03T12:48:34.648+0000] {taskinstance.py:441} INFO - ::group::Post task execution logs
[2025-07-03T12:48:34.648+0000] {taskinstance.py:2890} ERROR - Task failed with exception
Traceback (most recent call last):
  File "/home/airflow/.local/lib/python3.11/site-packages/airflow/models/taskinstance.py", line 465, in _execute_task
    result = _execute_callable(context=context, **execute_callable_kwargs)
             ^^^^^^^^^^^^^^^^^^^^^^^^^^^^^^^^^^^^^^^^^^^^^^^^^^^^^^^^^^^^^
  File "/home/airflow/.local/lib/python3.11/site-packages/airflow/models/taskinstance.py", line 432, in _execute_callable
    return execute_callable(context=context, **execute_callable_kwargs)
           ^^^^^^^^^^^^^^^^^^^^^^^^^^^^^^^^^^^^^^^^^^^^^^^^^^^^^^^^^^^^
  File "/home/airflow/.local/lib/python3.11/site-packages/airflow/models/baseoperator.py", line 400, in wrapper
    return func(self, *args, **kwargs)
           ^^^^^^^^^^^^^^^^^^^^^^^^^^^
  File "/home/airflow/.local/lib/python3.11/site-packages/airflow/operators/python.py", line 235, in execute
    return_value = self.execute_callable()
                   ^^^^^^^^^^^^^^^^^^^^^^^
  File "/home/airflow/.local/lib/python3.11/site-packages/airflow/operators/python.py", line 252, in execute_callable
    return self.python_callable(*self.op_args, **self.op_kwargs)
           ^^^^^^^^^^^^^^^^^^^^^^^^^^^^^^^^^^^^^^^^^^^^^^^^^^^^^
  File "/opt/airflow/dags/test_connection_to_minio.py", line 15, in connect_to_minio
    client = Minio(
             ^^^^^^
  File "/home/airflow/.local/lib/python3.11/site-packages/minio/api.py", line 153, in __init__
    self._base_url = BaseURL(
                     ^^^^^^^^
  File "/home/airflow/.local/lib/python3.11/site-packages/minio/helpers.py", line 551, in __init__
    url = _parse_url(endpoint)
          ^^^^^^^^^^^^^^^^^^^^
  File "/home/airflow/.local/lib/python3.11/site-packages/minio/helpers.py", line 512, in _parse_url
    raise ValueError("path in endpoint is not allowed")
ValueError: path in endpoint is not allowed
[2025-07-03T12:48:34.654+0000] {taskinstance.py:1205} INFO - Marking task as UP_FOR_RETRY. dag_id=connect_to_minio, task_id=connect_to_minio, execution_date=20250703T124833, start_date=20250703T124834, end_date=20250703T124834
[2025-07-03T12:48:34.659+0000] {standard_task_runner.py:110} ERROR - Failed to execute job 2 for task connect_to_minio (path in endpoint is not allowed; 220)
[2025-07-03T12:48:34.685+0000] {local_task_job_runner.py:240} INFO - Task exited with return code 1
[2025-07-03T12:48:34.697+0000] {taskinstance.py:3482} INFO - 0 downstream tasks scheduled from follow-on schedule check
[2025-07-03T12:48:34.698+0000] {local_task_job_runner.py:222} INFO - ::endgroup::
