[2025-07-03T12:50:17.307+0000] {local_task_job_runner.py:120} INFO - ::group::Pre task execution logs
[2025-07-03T12:50:17.324+0000] {taskinstance.py:2073} INFO - Dependencies all met for dep_context=non-requeueable deps ti=<TaskInstance: connect_to_minio.connect_to_minio manual__2025-07-03T12:48:33.639150+00:00 [queued]>
[2025-07-03T12:50:17.328+0000] {taskinstance.py:2073} INFO - Dependencies all met for dep_context=requeueable deps ti=<TaskInstance: connect_to_minio.connect_to_minio manual__2025-07-03T12:48:33.639150+00:00 [queued]>
[2025-07-03T12:50:17.328+0000] {taskinstance.py:2303} INFO - Starting attempt 2 of 3
[2025-07-03T12:50:17.334+0000] {taskinstance.py:2327} INFO - Executing <Task(PythonOperator): connect_to_minio> on 2025-07-03 12:48:33.639150+00:00
[2025-07-03T12:50:17.339+0000] {standard_task_runner.py:63} INFO - Started process 349 to run task
[2025-07-03T12:50:17.341+0000] {standard_task_runner.py:90} INFO - Running: ['***', 'tasks', 'run', 'connect_to_minio', 'connect_to_minio', 'manual__2025-07-03T12:48:33.639150+00:00', '--job-id', '3', '--raw', '--subdir', 'DAGS_FOLDER/test_connection_to_minio.py', '--cfg-path', '/tmp/tmpm3vn3k09']
[2025-07-03T12:50:17.342+0000] {standard_task_runner.py:91} INFO - Job 3: Subtask connect_to_minio
[2025-07-03T12:50:17.351+0000] {logging_mixin.py:188} WARNING - /home/***/.local/lib/python3.11/site-packages/***/settings.py:195 DeprecationWarning: The sql_alchemy_conn option in [core] has been moved to the sql_alchemy_conn option in [database] - the old setting has been used, but please update your config.
[2025-07-03T12:50:17.375+0000] {task_command.py:426} INFO - Running <TaskInstance: connect_to_minio.connect_to_minio manual__2025-07-03T12:48:33.639150+00:00 [running]> on host 8cef375d7ad3
[2025-07-03T12:50:17.424+0000] {taskinstance.py:2644} INFO - Exporting env vars: AIRFLOW_CTX_DAG_OWNER='hosi04' AIRFLOW_CTX_DAG_ID='connect_to_minio' AIRFLOW_CTX_TASK_ID='connect_to_minio' AIRFLOW_CTX_EXECUTION_DATE='2025-07-03T12:48:33.639150+00:00' AIRFLOW_CTX_TRY_NUMBER='2' AIRFLOW_CTX_DAG_RUN_ID='manual__2025-07-03T12:48:33.639150+00:00'
[2025-07-03T12:50:17.425+0000] {taskinstance.py:430} INFO - ::endgroup::
[2025-07-03T12:50:21.497+0000] {taskinstance.py:441} INFO - ::group::Post task execution logs
[2025-07-03T12:50:21.498+0000] {taskinstance.py:2890} ERROR - Task failed with exception
Traceback (most recent call last):
  File "/home/airflow/.local/lib/python3.11/site-packages/airflow/models/taskinstance.py", line 465, in _execute_task
    result = _execute_callable(context=context, **execute_callable_kwargs)
             ^^^^^^^^^^^^^^^^^^^^^^^^^^^^^^^^^^^^^^^^^^^^^^^^^^^^^^^^^^^^^
  File "/home/airflow/.local/lib/python3.11/site-packages/airflow/models/taskinstance.py", line 432, in _execute_callable
    return execute_callable(context=context, **execute_callable_kwargs)
           ^^^^^^^^^^^^^^^^^^^^^^^^^^^^^^^^^^^^^^^^^^^^^^^^^^^^^^^^^^^^
  File "/home/airflow/.local/lib/python3.11/site-packages/airflow/models/baseoperator.py", line 400, in wrapper
    return func(self, *args, **kwargs)
           ^^^^^^^^^^^^^^^^^^^^^^^^^^^
  File "/home/airflow/.local/lib/python3.11/site-packages/airflow/operators/python.py", line 235, in execute
    return_value = self.execute_callable()
                   ^^^^^^^^^^^^^^^^^^^^^^^
  File "/home/airflow/.local/lib/python3.11/site-packages/airflow/operators/python.py", line 252, in execute_callable
    return self.python_callable(*self.op_args, **self.op_kwargs)
           ^^^^^^^^^^^^^^^^^^^^^^^^^^^^^^^^^^^^^^^^^^^^^^^^^^^^^
  File "/opt/airflow/dags/test_connection_to_minio.py", line 34, in connect_to_minio
    for obj in objects:
  File "/home/airflow/.local/lib/python3.11/site-packages/minio/api.py", line 3191, in _list_objects
    response = self._execute(
               ^^^^^^^^^^^^^^
  File "/home/airflow/.local/lib/python3.11/site-packages/minio/api.py", line 438, in _execute
    region = self._get_region(bucket_name)
             ^^^^^^^^^^^^^^^^^^^^^^^^^^^^^
  File "/home/airflow/.local/lib/python3.11/site-packages/minio/api.py", line 495, in _get_region
    response = self._url_open(
               ^^^^^^^^^^^^^^^
  File "/home/airflow/.local/lib/python3.11/site-packages/minio/api.py", line 348, in _url_open
    raise InvalidResponseError(
minio.error.InvalidResponseError: non-XML response from server; Response code: 400, Content-Type: text/xml; charset=utf-8, Body: <?xml version="1.0" encoding="UTF-8"?><Error><Code>InvalidArgument</Code><Message>S3 API Requests must be made to API port.</Message><RequestId>0</RequestId></Error>
[2025-07-03T12:50:21.508+0000] {taskinstance.py:1205} INFO - Marking task as UP_FOR_RETRY. dag_id=connect_to_minio, task_id=connect_to_minio, execution_date=20250703T124833, start_date=20250703T125017, end_date=20250703T125021
[2025-07-03T12:50:21.520+0000] {standard_task_runner.py:110} ERROR - Failed to execute job 3 for task connect_to_minio (non-XML response from server; Response code: 400, Content-Type: text/xml; charset=utf-8, Body: <?xml version="1.0" encoding="UTF-8"?><Error><Code>InvalidArgument</Code><Message>S3 API Requests must be made to API port.</Message><RequestId>0</RequestId></Error>; 349)
[2025-07-03T12:50:21.562+0000] {local_task_job_runner.py:240} INFO - Task exited with return code 1
[2025-07-03T12:50:21.576+0000] {taskinstance.py:3482} INFO - 0 downstream tasks scheduled from follow-on schedule check
[2025-07-03T12:50:21.577+0000] {local_task_job_runner.py:222} INFO - ::endgroup::
