[2025-07-03T13:01:49.286+0000] {task_context_logger.py:104} ERROR - Executor reports task instance <TaskInstance: connect_to_minio.connect_to_minio manual__2025-07-03T12:48:33.639150+00:00 [queued]> finished (failed) although the task says it's queued. (Info: None) Was the task killed externally?
