[2025-07-03T13:15:02.458+0000] {task_context_logger.py:104} ERROR - Executor reports task instance <TaskInstance: minio_data_viewer.explore_bucket_structure manual__2025-07-03T13:07:20.235679+00:00 [queued]> finished (failed) although the task says it's queued. (Info: None) Was the task killed externally?
